Workbook

Sheet Assumptions
A1: 2051 E MAPLE AVE - VALUE ADD UNDERWRITING
D2: NOTES / SOURCE | F2: LEVERED IRR : RENT (DOWN) X PURCHASE PRICE (ACROSS)
B3: PROPERTY | F3: =Returns!C30 -> 0.00063656867 | G3: 8500000 | H3: 9000000 | I3: 9500000 | J3: 10000000 | K3: 10800000
B4: ADDRESS | C4: 2051 E Maple Ave, El Segundo | F4: 1.8 | G4: 0.046955821 | H4: 0.0237829 | I4: 0.0010617048 | J4: -0.021338913 | K4: -0.056826332
B5: BUILDING SF | C5: 32081 | D5: LoopNet / Colliers brochure | F5: 1.9 | G5: 0.073377374 | H5: 0.050825801 | I5: 0.028821775 | J5: 0.0072444886 | K5: -0.02666959
B6: LAND SF | C6: 52272 | D6: 1.20 AC per LoopNet | F6: 2 | G6: 0.097842532 | H6: 0.075764778 | I6: 0.054308578 | J6: 0.033359119 | K6: 0.00063656867
B7: YEAR BUILT | C7: 1953 | D7: LoopNet; Class C | F7: 2.1 | G7: 0.12066824 | H7: 0.09895491 | I7: 0.077922508 | J7: 0.057459626 | K7: 0.025658479
B8: PURCHASE PRICE | C8: 10800000 | D8: LoopNet asking price; on market since 4/13/2023 | F8: 2.2 | G8: 0.14209797 | H8: 0.12066581 | I8: 0.099963742 | J8: 0.079882184 | K8: 0.048804381
B9: PRICE PER BUILDING SF | C9: =C8/C5 -> 336.64786 | F9: 2.3 | G9: 0.16232311 | H9: 0.14110737 | I9: 0.12066359 | J9: 0.10088286 | K9: 0.070378986
B10: CLOSING COSTS (%) | C10: 0.02 | D10: Estimate: title, escrow, legal, due diligence
B11: CLOSING COSTS ($) | C11: =C8*C10 -> 216000
B12: ANALYSIS DATE | C12: 46631 | D12: Assumed closing date
B14: RENOVATION
B15: RENOVATION COST /SF | C15: 50 | D15: Estimate for 1953 Class C (roof, HVAC, power, office, seismic check); verify with contractor bids
B16: RENOVATION BUDGET | C16: =C15*C5 -> 1604050
B17: CONTINGENCY (%) | C17: 0.1 | D17: Standard contingency for older building
B18: CONTINGENCY ($) | C18: =C16*C17 -> 160405
B19: TOTAL RENOVATION | C19: =C16+C18 -> 1764455
B20: RENOVATION MONTHS | C20: 6 | D20: Assumed renovation schedule
B22: LEASING
B23: RENT($/SF/MO,NNN) | C23: 2 | D23: Linked to Comps tab: avg of 3 NNN asking comps = $1.98
B24: RENT GROWTH | C24: 0.035 | D24: Typical LA industrial annual escalator (3-4%)
B25: LEASE TERM (MONTHS) | C25: 60 | D25: 5-year lease, matches comp terms
B26: LEASE UP MONTHS (AFTER RENO) | C26: 6 | D26: Conservative: 3 nearby comps currently vacant
B27: FREE RENT (MONTHS) | C27: 3 | D27: Typical concession for 5-year lease
B28: TENANT IMPROV. ($/SF) | C28: 10 | D28: Allowance for tenant fit-out
B29: LEASING COMMIS. (% OF BASE RENT) | C29: 0.05 | D29: % of total base rent over lease term (simplified, no escalations)
B30: LEASE START (MONTH) | C30: =C20+C26+1 -> 13 | D30: Formula: renovation + lease-up + 1
B31: RENT START MONTH | C31: =C30+C27 -> 16 | D31: Formula: lease start + free rent
B33: OPERATING COST
B34: PROPERTY TAX RATE | C34: 0.012 | D34: ~1.1-1.2% of purchase price; CA reassesses at sale (Prop 13)
B35: PROPERTY TAX ($/YR) | C35: =C8*C34 -> 129600
B36: INSURANCE ($/SF/YR) | C36: 0.75 | D36: Placeholder; verify with insurance quote
B37: MAINTENANCE ($/SF/YR) | C37: 0.75 | D37: Placeholder; verify
B38: TOTAL EXPENSE ($/SF/MO) | C38: =(C35/C5+C36+C37)/12 -> 0.46164786 | D38: Paid by owner while vacant; reimbursed by tenant under NNN lease
B39: MANAGEMENT FEES | C39: 0.03 | D39: % of base rent; not reimbursed
B40: RESERVES ($/SF/YR) | C40: 0.15 | D40: Capital reserves; not reimbursed
B41: VACANCY AND CL | C41: 0.05 | D41: General vacancy / credit allowance after lease-up
B43: FINANCING
B44: LOAN TO COST | C44: 0.55 | D44: Loan sized on total cost before financing
...

Sheet Comps
A1: ADDRESS | B1: SUBMARKET | C1: ZONING | D1: SPACE SF | E1: YEAR BUILT | F1: CLEAR HEIGHT | G1: POWER (AMPS) | H1: OFFICE % | I1: ASKING RENT | J1: RENT TYPE | K1: TERM | L1: ASKING OR SIGNED | M1: NOTES
A2: 1924 E Maple Ave | B2: EL SEGUNDO | C2: CO | D2: 15650 | E2: 1955 (renov. 2025) | F2: 13' | G2: 1600 | H2: 0.13 | I2: 2.3 | J2: NNN | K2: 5 YRS | L2: ASKING | M2: Renovated 2025; 52 parking spaces
A3: 4928 W Rosecrans | B3: HAWTHORNE | C3: M2 | D3: 21252 | E3: 1979 | F3: 22' | G3: 400 | H3: 0.22 | I3: 1.89 | J3: NNN | K3: 5 YRS | L3: ASKING | M3: Exterior renovated; multi-tenant park; low power
A4: 1921 E Mariposa Ave | B4: EL SEGUNDO | C4: CO | D4: 62081 | E4: 1963 | F4: 16-20' (EST) | G4: 2000 | H4: N/A | I4: 1.76 | J4: NNN | K4: SHORT TERM OK | L4: ASKING | M4: Heavy power; land size differs (2.00 vs 2.92 AC)
H6: AVG RENT | I6: =AVERAGE(I2:I4) -> 1.9833333
H7: SUBJECT RENT | I7: =Assumptions!C23 -> 2 | M7: Avg of comps; renovated condition offsets lower clear height and parking; M2 zoning a modest advantage

Sheet Sources and Uses
B1: SOURCES AND USES
C2: AMOUNT | D2: PERCENT OF TOTAL | E2: PER SF
B3: USES
B4: PURCHASE PRICE | C4: =Assumptions!C8 -> 10800000 | D4: =C4/$C$12 -> 0.7973089 | E4: =C4/Assumptions!$C$5 -> 336.64786
B5: CLOSING COSTS | C5: =Assumptions!C11 -> 216000 | D5: =C5/$C$12 -> 0.015946178 | E5: =C5/Assumptions!$C$5 -> 6.7329572
B6: RENOVATION | C6: =Assumptions!C19 -> 1764455 | D6: =C6/$C$12 -> 0.13026071 | E6: =C6/Assumptions!$C$5 -> 55
B7: TENANT IMPROV. | C7: =Assumptions!C28*Assumptions!C5 -> 320810 | D7: =C7/$C$12 -> 0.023683766 | E7: =C7/Assumptions!$C$5 -> 10
B8: LEASING COMMISSION | C8: =Assumptions!C29*Assumptions!C23*Assumptions!C5*Assumptions!C25 -> 192486 | D8: =C8/$C$12 -> 0.014210259 | E8: =C8/Assumptions!$C$5 -> 6
B9: CARRY COST WHILE VACANT | C9: =Assumptions!C38*Assumptions!C5*(Assumptions!C30-1) -> 177721.5 | D9: =C9/$C$12 -> 0.013120272 | E9: =C9/Assumptions!$C$5 -> 5.5397743
B10: TOTAL BEFORE FINANCING | C10: =SUM(C4:C9) -> 13471472 | D10: =C10/$C$12 -> 0.99453008 | E10: =C10/Assumptions!$C$5 -> 419.92059
B11: LOAN FEE | C11: =C15*Assumptions!C47 -> 74093.099 | D11: =C11/$C$12 -> 0.0054699155 | E11: =C11/Assumptions!$C$5 -> 2.3095633
B12: TOTAL USES | C12: =C10+C11 -> 13545566 | D12: =C12/$C$12 -> 1 | E12: =C12/Assumptions!$C$5 -> 422.23015
B14: SOURCES
B15: LOAN AMOUNT | C15: =C10*Assumptions!C44 -> 7409309.9 | D15: =C15/$C$12 -> 0.54699155 | E15: =C15/Assumptions!$C$5 -> 230.95633
B16: EQUITY | C16: =C12-C15 -> 6136255.7 | D16: =C16/$C$12 -> 0.45300845 | E16: =C16/Assumptions!$C$5 -> 191.27383
B17: TOTAL SOURCES | C17: =C15+C16 -> 13545566 | D17: =C17/$C$12 -> 1 | E17: =C17/Assumptions!$C$5 -> 422.23015
B19: CHECK | C19: =C17-C12 -> 0

Sheet Cash Flow
B1: MONTHLY CASH FLOW | C1: Month 0 = closing | BL1: Month 61: NOI only, used for exit value
B2: MONTH | C2: 0 | D2: =C2+1 -> 1 | E2: =D2+1 -> 2 | F2: =E2+1 -> 3 | G2: =F2+1 -> 4 | H2: =G2+1 -> 5 | I2: =H2+1 -> 6 | J2: =I2+1 -> 7 | K2: =J2+1 -> 8 | ... BL2: =BK2+1 -> 61
B3: DATE | C3: =Assumptions!C12 -> 46631 | D3: =EDATE(C3,1) -> 46661 | E3: =EDATE(D3,1) -> 46692 | F3: =EDATE(E3,1) -> 46722 | G3: =EDATE(F3,1) -> 46753 | H3: =EDATE(G3,1) -> 46784 | I3: =EDATE(H3,1) -> 46813 | J3: =EDATE(I3,1) -> 46844 | K3: =EDATE(J3,1) -> 46874 | ... BL3: =EDATE(BK3,1) -> 48488
B4: LEASE YEAR | D4: =IF(D$2<Assumptions!$C$30,0,INT((D$2-Assumptions!$C$30)/12)+1) -> 0 | E4: =IF(E$2<Assumptions!$C$30,0,INT((E$2-Assumptions!$C$30)/12)+1) -> 0 | F4: =IF(F$2<Assumptions!$C$30,0,INT((F$2-Assumptions!$C$30)/12)+1) -> 0 | G4: =IF(G$2<Assumptions!$C$30,0,INT((G$2-Assumptions!$C$30)/12)+1) -> 0 | H4: =IF(H$2<Assumptions!$C$30,0,INT((H$2-Assumptions!$C$30)/12)+1) -> 0 | I4: =IF(I$2<Assumptions!$C$30,0,INT((I$2-Assumptions!$C$30)/12)+1) -> 0 | J4: =IF(J$2<Assumptions!$C$30,0,INT((J$2-Assumptions!$C$30)/12)+1) -> 0 | K4: =IF(K$2<Assumptions!$C$30,0,INT((K$2-Assumptions!$C$30)/12)+1) -> 0 | ... BL4: =IF(BL$2<Assumptions!$C$30,0,INT((BL$2-Assumptions!$C$30)/12)+1) -> 5
B6: REVENUE
B7: Base rent | D7: =IF(D$2>=Assumptions!$C$31,Assumptions!$C$23*Assumptions!$C$5*(1+Assumptions!$C$24)^(D$4-1),0) -> 0 | E7: =IF(E$2>=Assumptions!$C$31,Assumptions!$C$23*Assumptions!$C$5*(1+Assumptions!$C$24)^(E$4-1),0) -> 0 | F7: =IF(F$2>=Assumptions!$C$31,Assumptions!$C$23*Assumptions!$C$5*(1+Assumptions!$C$24)^(F$4-1),0) -> 0 | G7: =IF(G$2>=Assumptions!$C$31,Assumptions!$C$23*Assumptions!$C$5*(1+Assumptions!$C$24)^(G$4-1),0) -> 0 | H7: =IF(H$2>=Assumptions!$C$31,Assumptions!$C$23*Assumptions!$C$5*(1+Assumptions!$C$24)^(H$4-1),0) -> 0 | I7: =IF(I$2>=Assumptions!$C$31,Assumptions!$C$23*Assumptions!$C$5*(1+Assumptions!$C$24)^(I$4-1),0) -> 0 | J7: =IF(J$2>=Assumptions!$C$31,Assumptions!$C$23*Assumptions!$C$5*(1+Assumptions!$C$24)^(J$4-1),0) -> 0 | K7: =IF(K$2>=Assumptions!$C$31,Assumptions!$C$23*Assumptions!$C$5*(1+Assumptions!$C$24)^(K$4-1),0) -> 0 | ... BL7: =IF(BL$2>=Assumptions!$C$31,Assumptions!$C$23*Assumptions!$C$5*(1+Assumptions!$C$24)^(BL$4-1),0) -> 73627.371
B8: Expense reimbursements | D8: =IF(D$2>=Assumptions!$C$30,Assumptions!$C$38*Assumptions!$C$5,0) -> 0 | E8: =IF(E$2>=Assumptions!$C$30,Assumptions!$C$38*Assumptions!$C$5,0) -> 0 | F8: =IF(F$2>=Assumptions!$C$30,Assumptions!$C$38*Assumptions!$C$5,0) -> 0 | G8: =IF(G$2>=Assumptions!$C$30,Assumptions!$C$38*Assumptions!$C$5,0) -> 0 | H8: =IF(H$2>=Assumptions!$C$30,Assumptions!$C$38*Assumptions!$C$5,0) -> 0 | I8: =IF(I$2>=Assumptions!$C$30,Assumptions!$C$38*Assumptions!$C$5,0) -> 0 | J8: =IF(J$2>=Assumptions!$C$30,Assumptions!$C$38*Assumptions!$C$5,0) -> 0 | K8: =IF(K$2>=Assumptions!$C$30,Assumptions!$C$38*Assumptions!$C$5,0) -> 0 | ... BL8: =IF(BL$2>=Assumptions!$C$30,Assumptions!$C$38*Assumptions!$C$5,0) -> 14810.125
B9: Vacancy and credit loss | D9: =-(D7+D8)*Assumptions!$C$41 -> 0 | E9: =-(E7+E8)*Assumptions!$C$41 -> 0 | F9: =-(F7+F8)*Assumptions!$C$41 -> 0 | G9: =-(G7+G8)*Assumptions!$C$41 -> 0 | H9: =-(H7+H8)*Assumptions!$C$41 -> 0 | I9: =-(I7+I8)*Assumptions!$C$41 -> 0 | J9: =-(J7+J8)*Assumptions!$C$41 -> 0 | K9: =-(K7+K8)*Assumptions!$C$41 -> 0 | ... BL9: =-(BL7+BL8)*Assumptions!$C$41 -> -4421.8748
B10: EFFECTIVE GROSS INCOME | D10: =SUM(D7:D9) -> 0 | E10: =SUM(E7:E9) -> 0 | F10: =SUM(F7:F9) -> 0 | G10: =SUM(G7:G9) -> 0 | H10: =SUM(H7:H9) -> 0 | I10: =SUM(I7:I9) -> 0 | J10: =SUM(J7:J9) -> 0 | K10: =SUM(K7:K9) -> 0 | ... BL10: =SUM(BL7:BL9) -> 84015.621
B12: EXPENSES
B13: Operating expenses (taxes, insurance, maintenance) | D13: =-Assumptions!$C$38*Assumptions!$C$5 -> -14810.125 | E13: =-Assumptions!$C$38*Assumptions!$C$5 -> -14810.125 | F13: =-Assumptions!$C$38*Assumptions!$C$5 -> -14810.125 | G13: =-Assumptions!$C$38*Assumptions!$C$5 -> -14810.125 | H13: =-Assumptions!$C$38*Assumptions!$C$5 -> -14810.125 | I13: =-Assumptions!$C$38*Assumptions!$C$5 -> -14810.125 | J13: =-Assumptions!$C$38*Assumptions!$C$5 -> -14810.125 | K13: =-Assumptions!$C$38*Assumptions!$C$5 -> -14810.125 | ... BL13: =-Assumptions!$C$38*Assumptions!$C$5 -> -14810.125
B14: Management fee | D14: =-D7*Assumptions!$C$39 -> 0 | E14: =-E7*Assumptions!$C$39 -> 0 | F14: =-F7*Assumptions!$C$39 -> 0 | G14: =-G7*Assumptions!$C$39 -> 0 | H14: =-H7*Assumptions!$C$39 -> 0 | I14: =-I7*Assumptions!$C$39 -> 0 | J14: =-J7*Assumptions!$C$39 -> 0 | K14: =-K7*Assumptions!$C$39 -> 0 | ... BL14: =-BL7*Assumptions!$C$39 -> -2208.8211
B15: TOTAL EXPENSES | D15: =D13+D14 -> -14810.125 | E15: =E13+E14 -> -14810.125 | F15: =F13+F14 -> -14810.125 | G15: =G13+G14 -> -14810.125 | H15: =H13+H14 -> -14810.125 | I15: =I13+I14 -> -14810.125 | J15: =J13+J14 -> -14810.125 | K15: =K13+K14 -> -14810.125 | ... BL15: =BL13+BL14 -> -17018.946
B17: NET OPERATING INCOME | D17: =D10+D15 -> -14810.125 | E17: =E10+E15 -> -14810.125 | F17: =F10+F15 -> -14810.125 | G17: =G10+G15 -> -14810.125 | H17: =H10+H15 -> -14810.125 | I17: =I10+I15 -> -14810.125 | J17: =J10+J15 -> -14810.125 | K17: =K10+K15 -> -14810.125 | ... BL17: =BL10+BL15 -> 66996.675
B19: CAPITAL COSTS
B20: Renovation | D20: =IF(D$2<=Assumptions!$C$20,-Assumptions!$C$19/Assumptions!$C$20,0) -> -294075.83 | E20: =IF(E$2<=Assumptions!$C$20,-Assumptions!$C$19/Assumptions!$C$20,0) -> -294075.83 | F20: =IF(F$2<=Assumptions!$C$20,-Assumptions!$C$19/Assumptions!$C$20,0) -> -294075.83 | G20: =IF(G$2<=Assumptions!$C$20,-Assumptions!$C$19/Assumptions!$C$20,0) -> -294075.83 | H20: =IF(H$2<=Assumptions!$C$20,-Assumptions!$C$19/Assumptions!$C$20,0) -> -294075.83 | I20: =IF(I$2<=Assumptions!$C$20,-Assumptions!$C$19/Assumptions!$C$20,0) -> -294075.83 | J20: =IF(J$2<=Assumptions!$C$20,-Assumptions!$C$19/Assumptions!$C$20,0) -> 0 | K20: =IF(K$2<=Assumptions!$C$20,-Assumptions!$C$19/Assumptions!$C$20,0) -> 0 | ... BK20: =IF(BK$2<=Assumptions!$C$20,-Assumptions!$C$19/Assumptions!$C$20,0) -> 0
B21: Tenant improvements | D21: =IF(D$2=Assumptions!$C$30,-Assumptions!$C$28*Assumptions!$C$5,0) -> 0 | E21: =IF(E$2=Assumptions!$C$30,-Assumptions!$C$28*Assumptions!$C$5,0) -> 0 | F21: =IF(F$2=Assumptions!$C$30,-Assumptions!$C$28*Assumptions!$C$5,0) -> 0 | G21: =IF(G$2=Assumptions!$C$30,-Assumptions!$C$28*Assumptions!$C$5,0) -> 0 | H21: =IF(H$2=Assumptions!$C$30,-Assumptions!$C$28*Assumptions!$C$5,0) -> 0 | I21: =IF(I$2=Assumptions!$C$30,-Assumptions!$C$28*Assumptions!$C$5,0) -> 0 | J21: =IF(J$2=Assumptions!$C$30,-Assumptions!$C$28*Assumptions!$C$5,0) -> 0 | K21: =IF(K$2=Assumptions!$C$30,-Assumptions!$C$28*Assumptions!$C$5,0) -> 0 | ... BK21: =IF(BK$2=Assumptions!$C$30,-Assumptions!$C$28*Assumptions!$C$5,0) -> 0
B22: Leasing commissions | D22: =IF(D$2=Assumptions!$C$30,-'Sources and Uses'!$C$8,0) -> 0 | E22: =IF(E$2=Assumptions!$C$30,-'Sources and Uses'!$C$8,0) -> 0 | F22: =IF(F$2=Assumptions!$C$30,-'Sources and Uses'!$C$8,0) -> 0 | G22: =IF(G$2=Assumptions!$C$30,-'Sources and Uses'!$C$8,0) -> 0 | H22: =IF(H$2=Assumptions!$C$30,-'Sources and Uses'!$C$8,0) -> 0 | I22: =IF(I$2=Assumptions!$C$30,-'Sources and Uses'!$C$8,0) -> 0 | J22: =IF(J$2=Assumptions!$C$30,-'Sources and Uses'!$C$8,0) -> 0 | K22: =IF(K$2=Assumptions!$C$30,-'Sources and Uses'!$C$8,0) -> 0 | ... BK22: =IF(BK$2=Assumptions!$C$30,-'Sources and Uses'!$C$8,0) -> 0
B23: Reserves | D23: =-Assumptions!$C$40*Assumptions!$C$5/12 -> -401.0125 | E23: =-Assumptions!$C$40*Assumptions!$C$5/12 -> -401.0125 | F23: =-Assumptions!$C$40*Assumptions!$C$5/12 -> -401.0125 | G23: =-Assumptions!$C$40*Assumptions!$C$5/12 -> -401.0125 | H23: =-Assumptions!$C$40*Assumptions!$C$5/12 -> -401.0125 | I23: =-Assumptions!$C$40*Assumptions!$C$5/12 -> -401.0125 | J23: =-Assumptions!$C$40*Assumptions!$C$5/12 -> -401.0125 | K23: =-Assumptions!$C$40*Assumptions!$C$5/12 -> -401.0125 | ... BK23: =-Assumptions!$C$40*Assumptions!$C$5/12 -> -401.0125
B24: TOTAL CAPITAL COSTS | D24: =SUM(D20:D23) -> -294476.85 | E24: =SUM(E20:E23) -> -294476.85 | F24: =SUM(F20:F23) -> -294476.85 | G24: =SUM(G20:G23) -> -294476.85 | H24: =SUM(H20:H23) -> -294476.85 | I24: =SUM(I20:I23) -> -294476.85 | J24: =SUM(J20:J23) -> -401.0125 | K24: =SUM(K20:K23) -> -401.0125 | ... BK24: =SUM(BK20:BK23) -> -401.0125
B26: PURCHASE AND SALE
B27: Purchase price + closing costs | C27: =-('Sources and Uses'!C4+'Sources and Uses'!C5) -> -11016000
B28: Net sale proceeds | D28: =IF(D$2=Assumptions!$C$50,(E17*12/Assumptions!$C$51)*(1-Assumptions!$C$52),0) -> 0 | E28: =IF(E$2=Assumptions!$C$50,(F17*12/Assumptions!$C$51)*(1-Assumptions!$C$52),0) -> 0 | F28: =IF(F$2=Assumptions!$C$50,(G17*12/Assumptions!$C$51)*(1-Assumptions!$C$52),0) -> 0 | G28: =IF(G$2=Assumptions!$C$50,(H17*12/Assumptions!$C$51)*(1-Assumptions!$C$52),0) -> 0 | H28: =IF(H$2=Assumptions!$C$50,(I17*12/Assumptions!$C$51)*(1-Assumptions!$C$52),0) -> 0 | I28: =IF(I$2=Assumptions!$C$50,(J17*12/Assumptions!$C$51)*(1-Assumptions!$C$52),0) -> 0 | J28: =IF(J$2=Assumptions!$C$50,(K17*12/Assumptions!$C$51)*(1-Assumptions!$C$52),0) -> 0 | K28: =IF(K$2=Assumptions!$C$50,(L17*12/Assumptions!$C$51)*(1-Assumptions!$C$52),0) -> 0 | ... BK28: =IF(BK$2=Assumptions!$C$50,(BL17*12/Assumptions!$C$51)*(1-Assumptions!$C$52),0) -> 13131348
B30: UNLEVERED CASH FLOW | C30: =SUM(C17,C24,C27,C28) -> -11016000 | D30: =SUM(D17,D24,D27,D28) -> -309286.97 | E30: =SUM(E17,E24,E27,E28) -> -309286.97 | F30: =SUM(F17,F24,F27,F28) -> -309286.97 | G30: =SUM(G17,G24,G27,G28) -> -309286.97 | H30: =SUM(H17,H24,H27,H28) -> -309286.97 | I30: =SUM(I17,I24,I27,I28) -> -309286.97 | J30: =SUM(J17,J24,J27,J28) -> -15211.138 | ... BK30: =SUM(BK17,BK24,BK27,BK28) -> 13195653
B32: FINANCING
B33: Loan proceeds | C33: ='Sources and Uses'!C15 -> 7409309.9
B34: Loan fee | C34: =-'Sources and Uses'!C11 -> -74093.099
B35: Interest (interest-only) | D35: =IF(D$2<=Assumptions!$C$50,-'Sources and Uses'!$C$15*Assumptions!$C$45/12,0) -> -38590.156 | E35: =IF(E$2<=Assumptions!$C$50,-'Sources and Uses'!$C$15*Assumptions!$C$45/12,0) -> -38590.156 | F35: =IF(F$2<=Assumptions!$C$50,-'Sources and Uses'!$C$15*Assumptions!$C$45/12,0) -> -38590.156 | G35: =IF(G$2<=Assumptions!$C$50,-'Sources and Uses'!$C$15*Assumptions!$C$45/12,0) -> -38590.156 | H35: =IF(H$2<=Assumptions!$C$50,-'Sources and Uses'!$C$15*Assumptions!$C$45/12,0) -> -38590.156 | I35: =IF(I$2<=Assumptions!$C$50,-'Sources and Uses'!$C$15*Assumptions!$C$45/12,0) -> -38590.156 | J35: =IF(J$2<=Assumptions!$C$50,-'Sources and Uses'!$C$15*Assumptions!$C$45/12,0) -> -38590.156 | K35: =IF(K$2<=Assumptions!$C$50,-'Sources and Uses'!$C$15*Assumptions!$C$45/12,0) -> -38590.156 | ... BK35: =IF(BK$2<=Assumptions!$C$50,-'Sources and Uses'!$C$15*Assumptions!$C$45/12,0) -> -38590.156
B36: Loan repayment | D36: =IF(D$2=Assumptions!$C$50,-'Sources and Uses'!$C$15,0) -> 0 | E36: =IF(E$2=Assumptions!$C$50,-'Sources and Uses'!$C$15,0) -> 0 | F36: =IF(F$2=Assumptions!$C$50,-'Sources and Uses'!$C$15,0) -> 0 | G36: =IF(G$2=Assumptions!$C$50,-'Sources and Uses'!$C$15,0) -> 0 | H36: =IF(H$2=Assumptions!$C$50,-'Sources and Uses'!$C$15,0) -> 0 | I36: =IF(I$2=Assumptions!$C$50,-'Sources and Uses'!$C$15,0) -> 0 | J36: =IF(J$2=Assumptions!$C$50,-'Sources and Uses'!$C$15,0) -> 0 | K36: =IF(K$2=Assumptions!$C$50,-'Sources and Uses'!$C$15,0) -> 0 | ... BK36: =IF(BK$2=Assumptions!$C$50,-'Sources and Uses'!$C$15,0) -> -7409309.9
B38: LEVERED CASH FLOW | C38: =C30+C33+C34+C35+C36 -> -3680783.2 | D38: =D30+D33+D34+D35+D36 -> -347877.13 | E38: =E30+E33+E34+E35+E36 -> -347877.13 | F38: =F30+F33+F34+F35+F36 -> -347877.13 | G38: =G30+G33+G34+G35+G36 -> -347877.13 | H38: =H30+H33+H34+H35+H36 -> -347877.13 | I38: =I30+I33+I34+I35+I36 -> -347877.13 | J38: =J30+J33+J34+J35+J36 -> -53801.293 | ... BK38: =BK30+BK33+BK34+BK35+BK36 -> 5747753.3
B40: Cumulative levered cash flow | C40: =C38 -> -3680783.2 | D40: =C40+D38 -> -4028660.4 | E40: =D40+E38 -> -4376537.5 | F40: =E40+F38 -> -4724414.6 | G40: =F40+G38 -> -5072291.7 | H40: =G40+H38 -> -5420168.9 | I40: =H40+I38 -> -5768046 | J40: =I40+J38 -> -5821847.3 | K40: =J40+K38 -> -5875648.6 | ... BK40: =BJ40+BK38 -> 19329.546

Sheet Annual Summary
B1: ANNUAL SUMMARY
B2: PERIOD | C2: CLOSING | D2: YEAR 1 | E2: YEAR 2 | F2: YEAR 3 | G2: YEAR 4 | H2: YEAR 5 | I2: TOTAL
B3: Start month | D3: =12*0+1 -> 1 | E3: =12*1+1 -> 13 | F3: =12*2+1 -> 25 | G3: =12*3+1 -> 37 | H3: =12*4+1 -> 49
B4: End month | D4: =12*1 -> 12 | E4: =12*2 -> 24 | F4: =12*3 -> 36 | G4: =12*4 -> 48 | H4: =12*5 -> 60
B6: Base rent | C6: 0 | D6: =SUMPRODUCT(('Cash Flow'!$D$2:$BK$2>=D$3)*('Cash Flow'!$D$2:$BK$2<=D$4)*'Cash Flow'!$D$7:$BK$7) -> 0 | E6: =SUMPRODUCT(('Cash Flow'!$D$2:$BK$2>=E$3)*('Cash Flow'!$D$2:$BK$2<=E$4)*'Cash Flow'!$D$7:$BK$7) -> 577458 | F6: =SUMPRODUCT(('Cash Flow'!$D$2:$BK$2>=F$3)*('Cash Flow'!$D$2:$BK$2<=F$4)*'Cash Flow'!$D$7:$BK$7) -> 796892.04 | G6: =SUMPRODUCT(('Cash Flow'!$D$2:$BK$2>=G$3)*('Cash Flow'!$D$2:$BK$2<=G$4)*'Cash Flow'!$D$7:$BK$7) -> 824783.26 | H6: =SUMPRODUCT(('Cash Flow'!$D$2:$BK$2>=H$3)*('Cash Flow'!$D$2:$BK$2<=H$4)*'Cash Flow'!$D$7:$BK$7) -> 853650.68 | I6: =SUM(C6:H6) -> 3052784
B7: Expense reimbursements | C7: 0 | D7: =SUMPRODUCT(('Cash Flow'!$D$2:$BK$2>=D$3)*('Cash Flow'!$D$2:$BK$2<=D$4)*'Cash Flow'!$D$8:$BK$8) -> 0 | E7: =SUMPRODUCT(('Cash Flow'!$D$2:$BK$2>=E$3)*('Cash Flow'!$D$2:$BK$2<=E$4)*'Cash Flow'!$D$8:$BK$8) -> 177721.5 | F7: =SUMPRODUCT(('Cash Flow'!$D$2:$BK$2>=F$3)*('Cash Flow'!$D$2:$BK$2<=F$4)*'Cash Flow'!$D$8:$BK$8) -> 177721.5 | G7: =SUMPRODUCT(('Cash Flow'!$D$2:$BK$2>=G$3)*('Cash Flow'!$D$2:$BK$2<=G$4)*'Cash Flow'!$D$8:$BK$8) -> 177721.5 | H7: =SUMPRODUCT(('Cash Flow'!$D$2:$BK$2>=H$3)*('Cash Flow'!$D$2:$BK$2<=H$4)*'Cash Flow'!$D$8:$BK$8) -> 177721.5 | I7: =SUM(C7:H7) -> 710886
B8: Vacancy and credit loss | C8: 0 | D8: =SUMPRODUCT(('Cash Flow'!$D$2:$BK$2>=D$3)*('Cash Flow'!$D$2:$BK$2<=D$4)*'Cash Flow'!$D$9:$BK$9) -> 0 | E8: =SUMPRODUCT(('Cash Flow'!$D$2:$BK$2>=E$3)*('Cash Flow'!$D$2:$BK$2<=E$4)*'Cash Flow'!$D$9:$BK$9) -> -37758.975 | F8: =SUMPRODUCT(('Cash Flow'!$D$2:$BK$2>=F$3)*('Cash Flow'!$D$2:$BK$2<=F$4)*'Cash Flow'!$D$9:$BK$9) -> -48730.677 | G8: =SUMPRODUCT(('Cash Flow'!$D$2:$BK$2>=G$3)*('Cash Flow'!$D$2:$BK$2<=G$4)*'Cash Flow'!$D$9:$BK$9) -> -50125.238 | H8: =SUMPRODUCT(('Cash Flow'!$D$2:$BK$2>=H$3)*('Cash Flow'!$D$2:$BK$2<=H$4)*'Cash Flow'!$D$9:$BK$9) -> -51568.609 | I8: =SUM(C8:H8) -> -188183.5
B9: EFFECTIVE GROSS INCOME | C9: 0 | D9: =SUMPRODUCT(('Cash Flow'!$D$2:$BK$2>=D$3)*('Cash Flow'!$D$2:$BK$2<=D$4)*'Cash Flow'!$D$10:$BK$10) -> 0 | E9: =SUMPRODUCT(('Cash Flow'!$D$2:$BK$2>=E$3)*('Cash Flow'!$D$2:$BK$2<=E$4)*'Cash Flow'!$D$10:$BK$10) -> 717420.53 | F9: =SUMPRODUCT(('Cash Flow'!$D$2:$BK$2>=F$3)*('Cash Flow'!$D$2:$BK$2<=F$4)*'Cash Flow'!$D$10:$BK$10) -> 925882.86 | G9: =SUMPRODUCT(('Cash Flow'!$D$2:$BK$2>=G$3)*('Cash Flow'!$D$2:$BK$2<=G$4)*'Cash Flow'!$D$10:$BK$10) -> 952379.52 | H9: =SUMPRODUCT(('Cash Flow'!$D$2:$BK$2>=H$3)*('Cash Flow'!$D$2:$BK$2<=H$4)*'Cash Flow'!$D$10:$BK$10) -> 979803.57 | I9: =SUM(C9:H9) -> 3575486.5
B10: Operating expenses | C10: 0 | D10: =SUMPRODUCT(('Cash Flow'!$D$2:$BK$2>=D$3)*('Cash Flow'!$D$2:$BK$2<=D$4)*'Cash Flow'!$D$13:$BK$13) -> -177721.5 | E10: =SUMPRODUCT(('Cash Flow'!$D$2:$BK$2>=E$3)*('Cash Flow'!$D$2:$BK$2<=E$4)*'Cash Flow'!$D$13:$BK$13) -> -177721.5 | F10: =SUMPRODUCT(('Cash Flow'!$D$2:$BK$2>=F$3)*('Cash Flow'!$D$2:$BK$2<=F$4)*'Cash Flow'!$D$13:$BK$13) -> -177721.5 | G10: =SUMPRODUCT(('Cash Flow'!$D$2:$BK$2>=G$3)*('Cash Flow'!$D$2:$BK$2<=G$4)*'Cash Flow'!$D$13:$BK$13) -> -177721.5 | H10: =SUMPRODUCT(('Cash Flow'!$D$2:$BK$2>=H$3)*('Cash Flow'!$D$2:$BK$2<=H$4)*'Cash Flow'!$D$13:$BK$13) -> -177721.5 | I10: =SUM(C10:H10) -> -888607.5
B11: Management fee | C11: 0 | D11: =SUMPRODUCT(('Cash Flow'!$D$2:$BK$2>=D$3)*('Cash Flow'!$D$2:$BK$2<=D$4)*'Cash Flow'!$D$14:$BK$14) -> 0 | E11: =SUMPRODUCT(('Cash Flow'!$D$2:$BK$2>=E$3)*('Cash Flow'!$D$2:$BK$2<=E$4)*'Cash Flow'!$D$14:$BK$14) -> -17323.74 | F11: =SUMPRODUCT(('Cash Flow'!$D$2:$BK$2>=F$3)*('Cash Flow'!$D$2:$BK$2<=F$4)*'Cash Flow'!$D$14:$BK$14) -> -23906.761 | G11: =SUMPRODUCT(('Cash Flow'!$D$2:$BK$2>=G$3)*('Cash Flow'!$D$2:$BK$2<=G$4)*'Cash Flow'!$D$14:$BK$14) -> -24743.498 | H11: =SUMPRODUCT(('Cash Flow'!$D$2:$BK$2>=H$3)*('Cash Flow'!$D$2:$BK$2<=H$4)*'Cash Flow'!$D$14:$BK$14) -> -25609.52 | I11: =SUM(C11:H11) -> -91583.519
B12: NET OPERATING INCOME | C12: 0 | D12: =SUMPRODUCT(('Cash Flow'!$D$2:$BK$2>=D$3)*('Cash Flow'!$D$2:$BK$2<=D$4)*'Cash Flow'!$D$17:$BK$17) -> -177721.5 | E12: =SUMPRODUCT(('Cash Flow'!$D$2:$BK$2>=E$3)*('Cash Flow'!$D$2:$BK$2<=E$4)*'Cash Flow'!$D$17:$BK$17) -> 522375.29 | F12: =SUMPRODUCT(('Cash Flow'!$D$2:$BK$2>=F$3)*('Cash Flow'!$D$2:$BK$2<=F$4)*'Cash Flow'!$D$17:$BK$17) -> 724254.6 | G12: =SUMPRODUCT(('Cash Flow'!$D$2:$BK$2>=G$3)*('Cash Flow'!$D$2:$BK$2<=G$4)*'Cash Flow'!$D$17:$BK$17) -> 749914.53 | H12: =SUMPRODUCT(('Cash Flow'!$D$2:$BK$2>=H$3)*('Cash Flow'!$D$2:$BK$2<=H$4)*'Cash Flow'!$D$17:$BK$17) -> 776472.55 | I12: =SUM(C12:H12) -> 2595295.5
B14: Capital costs | C14: 0 | D14: =SUMPRODUCT(('Cash Flow'!$D$2:$BK$2>=D$3)*('Cash Flow'!$D$2:$BK$2<=D$4)*'Cash Flow'!$D$24:$BK$24) -> -1769267.1 | E14: =SUMPRODUCT(('Cash Flow'!$D$2:$BK$2>=E$3)*('Cash Flow'!$D$2:$BK$2<=E$4)*'Cash Flow'!$D$24:$BK$24) -> -518108.15 | F14: =SUMPRODUCT(('Cash Flow'!$D$2:$BK$2>=F$3)*('Cash Flow'!$D$2:$BK$2<=F$4)*'Cash Flow'!$D$24:$BK$24) -> -4812.15 | G14: =SUMPRODUCT(('Cash Flow'!$D$2:$BK$2>=G$3)*('Cash Flow'!$D$2:$BK$2<=G$4)*'Cash Flow'!$D$24:$BK$24) -> -4812.15 | H14: =SUMPRODUCT(('Cash Flow'!$D$2:$BK$2>=H$3)*('Cash Flow'!$D$2:$BK$2<=H$4)*'Cash Flow'!$D$24:$BK$24) -> -4812.15 | I14: =SUM(C14:H14) -> -2301811.7
B15: Purchase + closing | C15: ='Cash Flow'!C27 -> -11016000 | D15: =SUMPRODUCT(('Cash Flow'!$D$2:$BK$2>=D$3)*('Cash Flow'!$D$2:$BK$2<=D$4)*'Cash Flow'!$D$27:$BK$27) -> 0 | E15: =SUMPRODUCT(('Cash Flow'!$D$2:$BK$2>=E$3)*('Cash Flow'!$D$2:$BK$2<=E$4)*'Cash Flow'!$D$27:$BK$27) -> 0 | F15: =SUMPRODUCT(('Cash Flow'!$D$2:$BK$2>=F$3)*('Cash Flow'!$D$2:$BK$2<=F$4)*'Cash Flow'!$D$27:$BK$27) -> 0 | G15: =SUMPRODUCT(('Cash Flow'!$D$2:$BK$2>=G$3)*('Cash Flow'!$D$2:$BK$2<=G$4)*'Cash Flow'!$D$27:$BK$27) -> 0 | H15: =SUMPRODUCT(('Cash Flow'!$D$2:$BK$2>=H$3)*('Cash Flow'!$D$2:$BK$2<=H$4)*'Cash Flow'!$D$27:$BK$27) -> 0 | I15: =SUM(C15:H15) -> -11016000
B16: Net sale proceeds | C16: 0 | D16: =SUMPRODUCT(('Cash Flow'!$D$2:$BK$2>=D$3)*('Cash Flow'!$D$2:$BK$2<=D$4)*'Cash Flow'!$D$28:$BK$28) -> 0 | E16: =SUMPRODUCT(('Cash Flow'!$D$2:$BK$2>=E$3)*('Cash Flow'!$D$2:$BK$2<=E$4)*'Cash Flow'!$D$28:$BK$28) -> 0 | F16: =SUMPRODUCT(('Cash Flow'!$D$2:$BK$2>=F$3)*('Cash Flow'!$D$2:$BK$2<=F$4)*'Cash Flow'!$D$28:$BK$28) -> 0 | G16: =SUMPRODUCT(('Cash Flow'!$D$2:$BK$2>=G$3)*('Cash Flow'!$D$2:$BK$2<=G$4)*'Cash Flow'!$D$28:$BK$28) -> 0 | H16: =SUMPRODUCT(('Cash Flow'!$D$2:$BK$2>=H$3)*('Cash Flow'!$D$2:$BK$2<=H$4)*'Cash Flow'!$D$28:$BK$28) -> 13131348 | I16: =SUM(C16:H16) -> 13131348
B17: UNLEVERED CASH FLOW | C17: ='Cash Flow'!C30 -> -11016000 | D17: =SUMPRODUCT(('Cash Flow'!$D$2:$BK$2>=D$3)*('Cash Flow'!$D$2:$BK$2<=D$4)*'Cash Flow'!$D$30:$BK$30) -> -1946988.6 | E17: =SUMPRODUCT(('Cash Flow'!$D$2:$BK$2>=E$3)*('Cash Flow'!$D$2:$BK$2<=E$4)*'Cash Flow'!$D$30:$BK$30) -> 4267.135 | F17: =SUMPRODUCT(('Cash Flow'!$D$2:$BK$2>=F$3)*('Cash Flow'!$D$2:$BK$2<=F$4)*'Cash Flow'!$D$30:$BK$30) -> 719442.45 | G17: =SUMPRODUCT(('Cash Flow'!$D$2:$BK$2>=G$3)*('Cash Flow'!$D$2:$BK$2<=G$4)*'Cash Flow'!$D$30:$BK$30) -> 745102.38 | H17: =SUMPRODUCT(('Cash Flow'!$D$2:$BK$2>=H$3)*('Cash Flow'!$D$2:$BK$2<=H$4)*'Cash Flow'!$D$30:$BK$30) -> 13903009 | I17: =SUM(C17:H17) -> 2408832
B19: Loan proceeds | C19: ='Cash Flow'!C33 -> 7409309.9 | D19: =SUMPRODUCT(('Cash Flow'!$D$2:$BK$2>=D$3)*('Cash Flow'!$D$2:$BK$2<=D$4)*'Cash Flow'!$D$33:$BK$33) -> 0 | E19: =SUMPRODUCT(('Cash Flow'!$D$2:$BK$2>=E$3)*('Cash Flow'!$D$2:$BK$2<=E$4)*'Cash Flow'!$D$33:$BK$33) -> 0 | F19: =SUMPRODUCT(('Cash Flow'!$D$2:$BK$2>=F$3)*('Cash Flow'!$D$2:$BK$2<=F$4)*'Cash Flow'!$D$33:$BK$33) -> 0 | G19: =SUMPRODUCT(('Cash Flow'!$D$2:$BK$2>=G$3)*('Cash Flow'!$D$2:$BK$2<=G$4)*'Cash Flow'!$D$33:$BK$33) -> 0 | H19: =SUMPRODUCT(('Cash Flow'!$D$2:$BK$2>=H$3)*('Cash Flow'!$D$2:$BK$2<=H$4)*'Cash Flow'!$D$33:$BK$33) -> 0 | I19: =SUM(C19:H19) -> 7409309.9
B20: Loan fee | C20: ='Cash Flow'!C34 -> -74093.099 | D20: =SUMPRODUCT(('Cash Flow'!$D$2:$BK$2>=D$3)*('Cash Flow'!$D$2:$BK$2<=D$4)*'Cash Flow'!$D$34:$BK$34) -> 0 | E20: =SUMPRODUCT(('Cash Flow'!$D$2:$BK$2>=E$3)*('Cash Flow'!$D$2:$BK$2<=E$4)*'Cash Flow'!$D$34:$BK$34) -> 0 | F20: =SUMPRODUCT(('Cash Flow'!$D$2:$BK$2>=F$3)*('Cash Flow'!$D$2:$BK$2<=F$4)*'Cash Flow'!$D$34:$BK$34) -> 0 | G20: =SUMPRODUCT(('Cash Flow'!$D$2:$BK$2>=G$3)*('Cash Flow'!$D$2:$BK$2<=G$4)*'Cash Flow'!$D$34:$BK$34) -> 0 | H20: =SUMPRODUCT(('Cash Flow'!$D$2:$BK$2>=H$3)*('Cash Flow'!$D$2:$BK$2<=H$4)*'Cash Flow'!$D$34:$BK$34) -> 0 | I20: =SUM(C20:H20) -> -74093.099
B21: Interest | C21: 0 | D21: =SUMPRODUCT(('Cash Flow'!$D$2:$BK$2>=D$3)*('Cash Flow'!$D$2:$BK$2<=D$4)*'Cash Flow'!$D$35:$BK$35) -> -463081.87 | E21: =SUMPRODUCT(('Cash Flow'!$D$2:$BK$2>=E$3)*('Cash Flow'!$D$2:$BK$2<=E$4)*'Cash Flow'!$D$35:$BK$35) -> -463081.87 | F21: =SUMPRODUCT(('Cash Flow'!$D$2:$BK$2>=F$3)*('Cash Flow'!$D$2:$BK$2<=F$4)*'Cash Flow'!$D$35:$BK$35) -> -463081.87 | G21: =SUMPRODUCT(('Cash Flow'!$D$2:$BK$2>=G$3)*('Cash Flow'!$D$2:$BK$2<=G$4)*'Cash Flow'!$D$35:$BK$35) -> -463081.87 | H21: =SUMPRODUCT(('Cash Flow'!$D$2:$BK$2>=H$3)*('Cash Flow'!$D$2:$BK$2<=H$4)*'Cash Flow'!$D$35:$BK$35) -> -463081.87 | I21: =SUM(C21:H21) -> -2315409.3
B22: Loan repayment | C22: 0 | D22: =SUMPRODUCT(('Cash Flow'!$D$2:$BK$2>=D$3)*('Cash Flow'!$D$2:$BK$2<=D$4)*'Cash Flow'!$D$36:$BK$36) -> 0 | E22: =SUMPRODUCT(('Cash Flow'!$D$2:$BK$2>=E$3)*('Cash Flow'!$D$2:$BK$2<=E$4)*'Cash Flow'!$D$36:$BK$36) -> 0 | F22: =SUMPRODUCT(('Cash Flow'!$D$2:$BK$2>=F$3)*('Cash Flow'!$D$2:$BK$2<=F$4)*'Cash Flow'!$D$36:$BK$36) -> 0 | G22: =SUMPRODUCT(('Cash Flow'!$D$2:$BK$2>=G$3)*('Cash Flow'!$D$2:$BK$2<=G$4)*'Cash Flow'!$D$36:$BK$36) -> 0 | H22: =SUMPRODUCT(('Cash Flow'!$D$2:$BK$2>=H$3)*('Cash Flow'!$D$2:$BK$2<=H$4)*'Cash Flow'!$D$36:$BK$36) -> -7409309.9 | I22: =SUM(C22:H22) -> -7409309.9
B23: LEVERED CASH FLOW | C23: ='Cash Flow'!C38 -> -3680783.2 | D23: =SUMPRODUCT(('Cash Flow'!$D$2:$BK$2>=D$3)*('Cash Flow'!$D$2:$BK$2<=D$4)*'Cash Flow'!$D$38:$BK$38) -> -2410070.5 | E23: =SUMPRODUCT(('Cash Flow'!$D$2:$BK$2>=E$3)*('Cash Flow'!$D$2:$BK$2<=E$4)*'Cash Flow'!$D$38:$BK$38) -> -458814.73 | F23: =SUMPRODUCT(('Cash Flow'!$D$2:$BK$2>=F$3)*('Cash Flow'!$D$2:$BK$2<=F$4)*'Cash Flow'!$D$38:$BK$38) -> 256360.58 | G23: =SUMPRODUCT(('Cash Flow'!$D$2:$BK$2>=G$3)*('Cash Flow'!$D$2:$BK$2<=G$4)*'Cash Flow'!$D$38:$BK$38) -> 282020.51 | H23: =SUMPRODUCT(('Cash Flow'!$D$2:$BK$2>=H$3)*('Cash Flow'!$D$2:$BK$2<=H$4)*'Cash Flow'!$D$38:$BK$38) -> 6030616.9 | I23: =SUM(C23:H23) -> 19329.546
B25: Check: levered total = Cash Flow total | I25: =I23-SUM('Cash Flow'!C38:BK38) -> 8.3819032e-09

Sheet Returns
B1: RETURNS SUMMARY
B4: DEAL BASIS
B5: Purchase price | C5: =Assumptions!C8 -> 10800000 | D5: LoopNet asking
B6: Purchase price per SF | C6: =Assumptions!C9 -> 336.64786
B7: Total project cost (before financing) | C7: ='Sources and Uses'!C10 -> 13471472 | D7: Sources and Uses
B8: All-in cost per SF | C8: ='Sources and Uses'!E10 -> 419.92059 | D8: Purchase + renovation + leasing + carry
B10: STABILIZED OPERATIONS
B11: Stabilized NOI (annualized, first rent month) | C11: =INDEX('Cash Flow'!D17:BL17,Assumptions!C31)*12 -> 699462.41 | D11: NOI in rent start month x 12
B12: Yield on cost | C12: =C11/C7 -> 0.051921748 | D12: Stabilized NOI / total project cost
B13: Exit cap rate | C13: =Assumptions!C51 -> 0.06
B14: Development spread (yield on cost - exit cap) | C14: =C12-C13 -> -0.0080782517 | D14: Negative = renovation does not create value at this price
B16: EXIT
B17: Forward 12-month NOI at sale | C17: =INDEX('Cash Flow'!D17:BL17,Assumptions!C50+1)*12 -> 803960.1 | D17: Month 61 NOI x 12
B18: Gross sale price | C18: =C17/C13 -> 13399335
B19: Gross sale price per SF | C19: =C18/Assumptions!C5 -> 417.67199
B20: Net sale proceeds (after selling costs) | C20: =C18*(1-Assumptions!C52) -> 13131348
B22: UNLEVERED RETURNS
B23: Unlevered profit | C23: =SUM('Cash Flow'!C30:BK30) -> 2408832
B24: Unlevered IRR | C24: =XIRR('Cash Flow'!C30:BK30,'Cash Flow'!C3:BK3) -> 0.036426881 | D24: XIRR on monthly cash flows
B25: Unlevered IRR (monthly IRR check) | C25: =(1+IRR('Cash Flow'!C30:BK30,0.003))^12-1 -> 0.036465258 | D25: Should be close to XIRR
B26: Unlevered equity multiple | C26: =SUMIF('Cash Flow'!C30:BK30,">0")/-SUMIF('Cash Flow'!C30:BK30,"<0") -> 1.1787006
B28: LEVERED RETURNS
B29: Levered profit | C29: =SUM('Cash Flow'!C38:BK38) -> 19329.546
B30: Levered IRR | C30: =XIRR('Cash Flow'!C38:BK38,'Cash Flow'!C3:BK3) -> 0.00063656867 | D30: XIRR on monthly cash flows
B31: Levered IRR (monthly IRR check) | C31: =(1+IRR('Cash Flow'!C38:BK38,0.001))^12-1 -> 0.00063723658 | D31: Should be close to XIRR
B32: Levered equity multiple | C32: =SUMIF('Cash Flow'!C38:BK38,">0")/-SUMIF('Cash Flow'!C38:BK38,"<0") -> 1.002875
B33: Peak equity required | C33: =-MIN('Cash Flow'!C40:BK40) -> 6723344.8 | D33: Includes interest carry during renovation and lease-up (not in Sources and Uses)
B35: DEBT METRICS
B36: Loan amount | C36: ='Sources and Uses'!C15 -> 7409309.9
B37: Annual interest | C37: =C36*Assumptions!C45 -> 463081.87
B38: DSCR at stabilization | C38: =C11/C37 -> 1.5104509 | D38: Stabilized NOI / annual interest; lenders typically want 1.25x+
B39: Debt yield at stabilization | C39: =C11/C36 -> 0.094403179 | D39: Stabilized NOI / loan
B41: MAXIMUM PURCHASE PRICE
B42: Target yield on cost | C42: =Assumptions!C55 -> 0.065 | D42: Input on Assumptions tab
B43: Maximum price to hit target yield on cost | C43: =(12*Assumptions!$C$23*Assumptions!$C$5*(1-Assumptions!$C$41-Assumptions!$C$39)-Assumptions!$C$41*(Assumptions!$C$36+Assumptions!$C$37)*Assumptions!$C$5-Assumptions!$C$55*(Assumptions!$C$19+(Assumptions!$C$28*Assumptions!$C$5)+(Assumptions!$C$29*Assumptions!$C$23*Assumptions!$C$5*Assumptions!$C$25)+(Assumptions!$C$36+Assumptions!$C$37)*Assumptions!$C$5*(Assumptions!$C$30-1)/12))/(Assumptions!$C$55*(1+Assumptions!$C$10+Assumptions!$C$34*(Assumptions!$C$30-1)/12)+Assumptions!$C$41*Assumptions!$C$34) -> 8196818.7 | D43: Solved algebraically; all other assumptions held constant
B44: Discount to asking price | C44: =1-C43/C5 -> 0.2410353
B45: Check: yield on cost at maximum price | C45: =(12*Assumptions!$C$23*Assumptions!$C$5*(1-Assumptions!$C$41-Assumptions!$C$39)-Assumptions!$C$41*($C$43*Assumptions!$C$34+(Assumptions!$C$36+Assumptions!$C$37)*Assumptions!$C$5))/($C$43*(1+Assumptions!$C$10)+Assumptions!$C$19+(Assumptions!$C$28*Assumptions!$C$5)+(Assumptions!$C$29*Assumptions!$C$23*Assumptions!$C$5*Assumptions!$C$25)+($C$43*Assumptions!$C$34+(Assumptions!$C$36+Assumptions!$C$37)*Assumptions!$C$5)*(Assumptions!$C$30-1)/12) -> 0.065 | D45: Should equal target
B47: CONCLUSION (base case)
B48: At the $10.8M asking price, stabilized yield on cost (~5.2%) is below the 6.0% exit cap and the 6.25% loan rate, so renovation destroys value and leverage hurts returns (levered IRR ~0%). Even at $2.30 rents, levered IRR is only ~7%. A ~12% levered IRR needs roughly $9.5M at $2.30 rents or $9.0M at $2.20 (see Sensitivity); at $2.00 rents, a 6.5% yield on cost requires ~$8.2M.

Sheet Sensitivity
B1: SENSITIVITY ANALYSIS
B2: Blue = scenario values you can edit. Base case: $2.00 rent, $10.8M price.
B3: 1) YIELD ON COST: rent × purchase price (live formulas)
B4: Stabilized NOI ÷ total project cost; all other assumptions from Assumptions tab
B5: Rent ($/SF/mo NNN) ↓ | C5: 8500000 | D5: 9000000 | E5: 9500000 | F5: 10000000 | G5: 10800000
B6: 1.8 | C6: =(12*$B6*Assumptions!$C$5*(1-Assumptions!$C$41-Assumptions!$C$39)-Assumptions!$C$41*(C$5*Assumptions!$C$34+(Assumptions!$C$36+Assumptions!$C$37)*Assumptions!$C$5))/(C$5*(1+Assumptions!$C$10)+Assumptions!$C$19+(Assumptions!$C$28*Assumptions!$C$5)+(Assumptions!$C$29*$B6*Assumptions!$C$5*Assumptions!$C$25)+(C$5*Assumptions!$C$34+(Assumptions!$C$36+Assumptions!$C$37)*Assumptions!$C$5)*(Assumptions!$C$30-1)/12) -> 0.056866951 | D6: =(12*$B6*Assumptions!$C$5*(1-Assumptions!$C$41-Assumptions!$C$39)-Assumptions!$C$41*(D$5*Assumptions!$C$34+(Assumptions!$C$36+Assumptions!$C$37)*Assumptions!$C$5))/(D$5*(1+Assumptions!$C$10)+Assumptions!$C$19+(Assumptions!$C$28*Assumptions!$C$5)+(Assumptions!$C$29*$B6*Assumptions!$C$5*Assumptions!$C$25)+(D$5*Assumptions!$C$34+(Assumptions!$C$36+Assumptions!$C$37)*Assumptions!$C$5)*(Assumptions!$C$30-1)/12) -> 0.054310305 | E6: =(12*$B6*Assumptions!$C$5*(1-Assumptions!$C$41-Assumptions!$C$39)-Assumptions!$C$41*(E$5*Assumptions!$C$34+(Assumptions!$C$36+Assumptions!$C$37)*Assumptions!$C$5))/(E$5*(1+Assumptions!$C$10)+Assumptions!$C$19+(Assumptions!$C$28*Assumptions!$C$5)+(Assumptions!$C$29*$B6*Assumptions!$C$5*Assumptions!$C$25)+(E$5*Assumptions!$C$34+(Assumptions!$C$36+Assumptions!$C$37)*Assumptions!$C$5)*(Assumptions!$C$30-1)/12) -> 0.051971522 | F6: =(12*$B6*Assumptions!$C$5*(1-Assumptions!$C$41-Assumptions!$C$39)-Assumptions!$C$41*(F$5*Assumptions!$C$34+(Assumptions!$C$36+Assumptions!$C$37)*Assumptions!$C$5))/(F$5*(1+Assumptions!$C$10)+Assumptions!$C$19+(Assumptions!$C$28*Assumptions!$C$5)+(Assumptions!$C$29*$B6*Assumptions!$C$5*Assumptions!$C$25)+(F$5*Assumptions!$C$34+(Assumptions!$C$36+Assumptions!$C$37)*Assumptions!$C$5)*(Assumptions!$C$30-1)/12) -> 0.049823893 | G6: =(12*$B6*Assumptions!$C$5*(1-Assumptions!$C$41-Assumptions!$C$39)-Assumptions!$C$41*(G$5*Assumptions!$C$34+(Assumptions!$C$36+Assumptions!$C$37)*Assumptions!$C$5))/(G$5*(1+Assumptions!$C$10)+Assumptions!$C$19+(Assumptions!$C$28*Assumptions!$C$5)+(Assumptions!$C$29*$B6*Assumptions!$C$5*Assumptions!$C$25)+(G$5*Assumptions!$C$34+(Assumptions!$C$36+Assumptions!$C$37)*Assumptions!$C$5)*(Assumptions!$C$30-1)/12) -> 0.046730382
B7: 1.9 | C7: =(12*$B7*Assumptions!$C$5*(1-Assumptions!$C$41-Assumptions!$C$39)-Assumptions!$C$41*(C$5*Assumptions!$C$34+(Assumptions!$C$36+Assumptions!$C$37)*Assumptions!$C$5))/(C$5*(1+Assumptions!$C$10)+Assumptions!$C$19+(Assumptions!$C$28*Assumptions!$C$5)+(Assumptions!$C$29*$B7*Assumptions!$C$5*Assumptions!$C$25)+(C$5*Assumptions!$C$34+(Assumptions!$C$36+Assumptions!$C$37)*Assumptions!$C$5)*(Assumptions!$C$30-1)/12) -> 0.060011732 | D7: =(12*$B7*Assumptions!$C$5*(1-Assumptions!$C$41-Assumptions!$C$39)-Assumptions!$C$41*(D$5*Assumptions!$C$34+(Assumptions!$C$36+Assumptions!$C$37)*Assumptions!$C$5))/(D$5*(1+Assumptions!$C$10)+Assumptions!$C$19+(Assumptions!$C$28*Assumptions!$C$5)+(Assumptions!$C$29*$B7*Assumptions!$C$5*Assumptions!$C$25)+(D$5*Assumptions!$C$34+(Assumptions!$C$36+Assumptions!$C$37)*Assumptions!$C$5)*(Assumptions!$C$30-1)/12) -> 0.057317369 | E7: =(12*$B7*Assumptions!$C$5*(1-Assumptions!$C$41-Assumptions!$C$39)-Assumptions!$C$41*(E$5*Assumptions!$C$34+(Assumptions!$C$36+Assumptions!$C$37)*Assumptions!$C$5))/(E$5*(1+Assumptions!$C$10)+Assumptions!$C$19+(Assumptions!$C$28*Assumptions!$C$5)+(Assumptions!$C$29*$B7*Assumptions!$C$5*Assumptions!$C$25)+(E$5*Assumptions!$C$34+(Assumptions!$C$36+Assumptions!$C$37)*Assumptions!$C$5)*(Assumptions!$C$30-1)/12) -> 0.054852423 | F7: =(12*$B7*Assumptions!$C$5*(1-Assumptions!$C$41-Assumptions!$C$39)-Assumptions!$C$41*(F$5*Assumptions!$C$34+(Assumptions!$C$36+Assumptions!$C$37)*Assumptions!$C$5))/(F$5*(1+Assumptions!$C$10)+Assumptions!$C$19+(Assumptions!$C$28*Assumptions!$C$5)+(Assumptions!$C$29*$B7*Assumptions!$C$5*Assumptions!$C$25)+(F$5*Assumptions!$C$34+(Assumptions!$C$36+Assumptions!$C$37)*Assumptions!$C$5)*(Assumptions!$C$30-1)/12) -> 0.052588788 | G7: =(12*$B7*Assumptions!$C$5*(1-Assumptions!$C$41-Assumptions!$C$39)-Assumptions!$C$41*(G$5*Assumptions!$C$34+(Assumptions!$C$36+Assumptions!$C$37)*Assumptions!$C$5))/(G$5*(1+Assumptions!$C$10)+Assumptions!$C$19+(Assumptions!$C$28*Assumptions!$C$5)+(Assumptions!$C$29*$B7*Assumptions!$C$5*Assumptions!$C$25)+(G$5*Assumptions!$C$34+(Assumptions!$C$36+Assumptions!$C$37)*Assumptions!$C$5)*(Assumptions!$C$30-1)/12) -> 0.049327921
B8: 2 | C8: =(12*$B8*Assumptions!$C$5*(1-Assumptions!$C$41-Assumptions!$C$39)-Assumptions!$C$41*(C$5*Assumptions!$C$34+(Assumptions!$C$36+Assumptions!$C$37)*Assumptions!$C$5))/(C$5*(1+Assumptions!$C$10)+Assumptions!$C$19+(Assumptions!$C$28*Assumptions!$C$5)+(Assumptions!$C$29*$B8*Assumptions!$C$5*Assumptions!$C$25)+(C$5*Assumptions!$C$34+(Assumptions!$C$36+Assumptions!$C$37)*Assumptions!$C$5)*(Assumptions!$C$30-1)/12) -> 0.063151059 | D8: =(12*$B8*Assumptions!$C$5*(1-Assumptions!$C$41-Assumptions!$C$39)-Assumptions!$C$41*(D$5*Assumptions!$C$34+(Assumptions!$C$36+Assumptions!$C$37)*Assumptions!$C$5))/(D$5*(1+Assumptions!$C$10)+Assumptions!$C$19+(Assumptions!$C$28*Assumptions!$C$5)+(Assumptions!$C$29*$B8*Assumptions!$C$5*Assumptions!$C$25)+(D$5*Assumptions!$C$34+(Assumptions!$C$36+Assumptions!$C$37)*Assumptions!$C$5)*(Assumptions!$C$30-1)/12) -> 0.06031945 | E8: =(12*$B8*Assumptions!$C$5*(1-Assumptions!$C$41-Assumptions!$C$39)-Assumptions!$C$41*(E$5*Assumptions!$C$34+(Assumptions!$C$36+Assumptions!$C$37)*Assumptions!$C$5))/(E$5*(1+Assumptions!$C$10)+Assumptions!$C$19+(Assumptions!$C$28*Assumptions!$C$5)+(Assumptions!$C$29*$B8*Assumptions!$C$5*Assumptions!$C$25)+(E$5*Assumptions!$C$34+(Assumptions!$C$36+Assumptions!$C$37)*Assumptions!$C$5)*(Assumptions!$C$30-1)/12) -> 0.057728752 | F8: =(12*$B8*Assumptions!$C$5*(1-Assumptions!$C$41-Assumptions!$C$39)-Assumptions!$C$41*(F$5*Assumptions!$C$34+(Assumptions!$C$36+Assumptions!$C$37)*Assumptions!$C$5))/(F$5*(1+Assumptions!$C$10)+Assumptions!$C$19+(Assumptions!$C$28*Assumptions!$C$5)+(Assumptions!$C$29*$B8*Assumptions!$C$5*Assumptions!$C$25)+(F$5*Assumptions!$C$34+(Assumptions!$C$36+Assumptions!$C$37)*Assumptions!$C$5)*(Assumptions!$C$30-1)/12) -> 0.055349475 | G8: =(12*$B8*Assumptions!$C$5*(1-Assumptions!$C$41-Assumptions!$C$39)-Assumptions!$C$41*(G$5*Assumptions!$C$34+(Assumptions!$C$36+Assumptions!$C$37)*Assumptions!$C$5))/(G$5*(1+Assumptions!$C$10)+Assumptions!$C$19+(Assumptions!$C$28*Assumptions!$C$5)+(Assumptions!$C$29*$B8*Assumptions!$C$5*Assumptions!$C$25)+(G$5*Assumptions!$C$34+(Assumptions!$C$36+Assumptions!$C$37)*Assumptions!$C$5)*(Assumptions!$C$30-1)/12) -> 0.051921748
B9: 2.1 | C9: =(12*$B9*Assumptions!$C$5*(1-Assumptions!$C$41-Assumptions!$C$39)-Assumptions!$C$41*(C$5*Assumptions!$C$34+(Assumptions!$C$36+Assumptions!$C$37)*Assumptions!$C$5))/(C$5*(1+Assumptions!$C$10)+Assumptions!$C$19+(Assumptions!$C$28*Assumptions!$C$5)+(Assumptions!$C$29*$B9*Assumptions!$C$5*Assumptions!$C$25)+(C$5*Assumptions!$C$34+(Assumptions!$C$36+Assumptions!$C$37)*Assumptions!$C$5)*(Assumptions!$C$30-1)/12) -> 0.066284946 | D9: =(12*$B9*Assumptions!$C$5*(1-Assumptions!$C$41-Assumptions!$C$39)-Assumptions!$C$41*(D$5*Assumptions!$C$34+(Assumptions!$C$36+Assumptions!$C$37)*Assumptions!$C$5))/(D$5*(1+Assumptions!$C$10)+Assumptions!$C$19+(Assumptions!$C$28*Assumptions!$C$5)+(Assumptions!$C$29*$B9*Assumptions!$C$5*Assumptions!$C$25)+(D$5*Assumptions!$C$34+(Assumptions!$C$36+Assumptions!$C$37)*Assumptions!$C$5)*(Assumptions!$C$30-1)/12) -> 0.06331656 | E9: =(12*$B9*Assumptions!$C$5*(1-Assumptions!$C$41-Assumptions!$C$39)-Assumptions!$C$41*(E$5*Assumptions!$C$34+(Assumptions!$C$36+Assumptions!$C$37)*Assumptions!$C$5))/(E$5*(1+Assumptions!$C$10)+Assumptions!$C$19+(Assumptions!$C$28*Assumptions!$C$5)+(Assumptions!$C$29*$B9*Assumptions!$C$5*Assumptions!$C$25)+(E$5*Assumptions!$C$34+(Assumptions!$C$36+Assumptions!$C$37)*Assumptions!$C$5)*(Assumptions!$C$30-1)/12) -> 0.060600521 | F9: =(12*$B9*Assumptions!$C$5*(1-Assumptions!$C$41-Assumptions!$C$39)-Assumptions!$C$41*(F$5*Assumptions!$C$34+(Assumptions!$C$36+Assumptions!$C$37)*Assumptions!$C$5))/(F$5*(1+Assumptions!$C$10)+Assumptions!$C$19+(Assumptions!$C$28*Assumptions!$C$5)+(Assumptions!$C$29*$B9*Assumptions!$C$5*Assumptions!$C$25)+(F$5*Assumptions!$C$34+(Assumptions!$C$36+Assumptions!$C$37)*Assumptions!$C$5)*(Assumptions!$C$30-1)/12) -> 0.058105963 | G9: =(12*$B9*Assumptions!$C$5*(1-Assumptions!$C$41-Assumptions!$C$39)-Assumptions!$C$41*(G$5*Assumptions!$C$34+(Assumptions!$C$36+Assumptions!$C$37)*Assumptions!$C$5))/(G$5*(1+Assumptions!$C$10)+Assumptions!$C$19+(Assumptions!$C$28*Assumptions!$C$5)+(Assumptions!$C$29*$B9*Assumptions!$C$5*Assumptions!$C$25)+(G$5*Assumptions!$C$34+(Assumptions!$C$36+Assumptions!$C$37)*Assumptions!$C$5)*(Assumptions!$C$30-1)/12) -> 0.054511872
B10: 2.2 | C10: =(12*$B10*Assumptions!$C$5*(1-Assumptions!$C$41-Assumptions!$C$39)-Assumptions!$C$41*(C$5*Assumptions!$C$34+(Assumptions!$C$36+Assumptions!$C$37)*Assumptions!$C$5))/(C$5*(1+Assumptions!$C$10)+Assumptions!$C$19+(Assumptions!$C$28*Assumptions!$C$5)+(Assumptions!$C$29*$B10*Assumptions!$C$5*Assumptions!$C$25)+(C$5*Assumptions!$C$34+(Assumptions!$C$36+Assumptions!$C$37)*Assumptions!$C$5)*(Assumptions!$C$30-1)/12) -> 0.069413407 | D10: =(12*$B10*Assumptions!$C$5*(1-Assumptions!$C$41-Assumptions!$C$39)-Assumptions!$C$41*(D$5*Assumptions!$C$34+(Assumptions!$C$36+Assumptions!$C$37)*Assumptions!$C$5))/(D$5*(1+Assumptions!$C$10)+Assumptions!$C$19+(Assumptions!$C$28*Assumptions!$C$5)+(Assumptions!$C$29*$B10*Assumptions!$C$5*Assumptions!$C$25)+(D$5*Assumptions!$C$34+(Assumptions!$C$36+Assumptions!$C$37)*Assumptions!$C$5)*(Assumptions!$C$30-1)/12) -> 0.06630871 | E10: =(12*$B10*Assumptions!$C$5*(1-Assumptions!$C$41-Assumptions!$C$39)-Assumptions!$C$41*(E$5*Assumptions!$C$34+(Assumptions!$C$36+Assumptions!$C$37)*Assumptions!$C$5))/(E$5*(1+Assumptions!$C$10)+Assumptions!$C$19+(Assumptions!$C$28*Assumptions!$C$5)+(Assumptions!$C$29*$B10*Assumptions!$C$5*Assumptions!$C$25)+(E$5*Assumptions!$C$34+(Assumptions!$C$36+Assumptions!$C$37)*Assumptions!$C$5)*(Assumptions!$C$30-1)/12) -> 0.063467739 | F10: =(12*$B10*Assumptions!$C$5*(1-Assumptions!$C$41-Assumptions!$C$39)-Assumptions!$C$41*(F$5*Assumptions!$C$34+(Assumptions!$C$36+Assumptions!$C$37)*Assumptions!$C$5))/(F$5*(1+Assumptions!$C$10)+Assumptions!$C$19+(Assumptions!$C$28*Assumptions!$C$5)+(Assumptions!$C$29*$B10*Assumptions!$C$5*Assumptions!$C$25)+(F$5*Assumptions!$C$34+(Assumptions!$C$36+Assumptions!$C$37)*Assumptions!$C$5)*(Assumptions!$C$30-1)/12) -> 0.060858262 | G10: =(12*$B10*Assumptions!$C$5*(1-Assumptions!$C$41-Assumptions!$C$39)-Assumptions!$C$41*(G$5*Assumptions!$C$34+(Assumptions!$C$36+Assumptions!$C$37)*Assumptions!$C$5))/(G$5*(1+Assumptions!$C$10)+Assumptions!$C$19+(Assumptions!$C$28*Assumptions!$C$5)+(Assumptions!$C$29*$B10*Assumptions!$C$5*Assumptions!$C$25)+(G$5*Assumptions!$C$34+(Assumptions!$C$36+Assumptions!$C$37)*Assumptions!$C$5)*(Assumptions!$C$30-1)/12) -> 0.057098301
B11: 2.3 | C11: =(12*$B11*Assumptions!$C$5*(1-Assumptions!$C$41-Assumptions!$C$39)-Assumptions!$C$41*(C$5*Assumptions!$C$34+(Assumptions!$C$36+Assumptions!$C$37)*Assumptions!$C$5))/(C$5*(1+Assumptions!$C$10)+Assumptions!$C$19+(Assumptions!$C$28*Assumptions!$C$5)+(Assumptions!$C$29*$B11*Assumptions!$C$5*Assumptions!$C$25)+(C$5*Assumptions!$C$34+(Assumptions!$C$36+Assumptions!$C$37)*Assumptions!$C$5)*(Assumptions!$C$30-1)/12) -> 0.072536456 | D11: =(12*$B11*Assumptions!$C$5*(1-Assumptions!$C$41-Assumptions!$C$39)-Assumptions!$C$41*(D$5*Assumptions!$C$34+(Assumptions!$C$36+Assumptions!$C$37)*Assumptions!$C$5))/(D$5*(1+Assumptions!$C$10)+Assumptions!$C$19+(Assumptions!$C$28*Assumptions!$C$5)+(Assumptions!$C$29*$B11*Assumptions!$C$5*Assumptions!$C$25)+(D$5*Assumptions!$C$34+(Assumptions!$C$36+Assumptions!$C$37)*Assumptions!$C$5)*(Assumptions!$C$30-1)/12) -> 0.069295913 | E11: =(12*$B11*Assumptions!$C$5*(1-Assumptions!$C$41-Assumptions!$C$39)-Assumptions!$C$41*(E$5*Assumptions!$C$34+(Assumptions!$C$36+Assumptions!$C$37)*Assumptions!$C$5))/(E$5*(1+Assumptions!$C$10)+Assumptions!$C$19+(Assumptions!$C$28*Assumptions!$C$5)+(Assumptions!$C$29*$B11*Assumptions!$C$5*Assumptions!$C$25)+(E$5*Assumptions!$C$34+(Assumptions!$C$36+Assumptions!$C$37)*Assumptions!$C$5)*(Assumptions!$C$30-1)/12) -> 0.066330419 | F11: =(12*$B11*Assumptions!$C$5*(1-Assumptions!$C$41-Assumptions!$C$39)-Assumptions!$C$41*(F$5*Assumptions!$C$34+(Assumptions!$C$36+Assumptions!$C$37)*Assumptions!$C$5))/(F$5*(1+Assumptions!$C$10)+Assumptions!$C$19+(Assumptions!$C$28*Assumptions!$C$5)+(Assumptions!$C$29*$B11*Assumptions!$C$5*Assumptions!$C$25)+(F$5*Assumptions!$C$34+(Assumptions!$C$36+Assumptions!$C$37)*Assumptions!$C$5)*(Assumptions!$C$30-1)/12) -> 0.06360638 | G11: =(12*$B11*Assumptions!$C$5*(1-Assumptions!$C$41-Assumptions!$C$39)-Assumptions!$C$41*(G$5*Assumptions!$C$34+(Assumptions!$C$36+Assumptions!$C$37)*Assumptions!$C$5))/(G$5*(1+Assumptions!$C$10)+Assumptions!$C$19+(Assumptions!$C$28*Assumptions!$C$5)+(Assumptions!$C$29*$B11*Assumptions!$C$5*Assumptions!$C$25)+(G$5*Assumptions!$C$34+(Assumptions!$C$36+Assumptions!$C$37)*Assumptions!$C$5)*(Assumptions!$C$30-1)/12) -> 0.059681042
B14: 2) MAXIMUM PURCHASE PRICE: rent × target yield on cost (live formulas)
B15: Price at which the deal hits each target yield on cost
B16: Rent ($/SF/mo NNN) ↓ | C16: 0.06 | D16: 0.0625 | E16: 0.065 | F16: 0.0675 | G16: 0.07
B17: 1.8 | C17: =(12*$B17*Assumptions!$C$5*(1-Assumptions!$C$41-Assumptions!$C$39)-Assumptions!$C$41*(Assumptions!$C$36+Assumptions!$C$37)*Assumptions!$C$5-C$16*(Assumptions!$C$19+(Assumptions!$C$28*Assumptions!$C$5)+(Assumptions!$C$29*$B17*Assumptions!$C$5*Assumptions!$C$25)+(Assumptions!$C$36+Assumptions!$C$37)*Assumptions!$C$5*(Assumptions!$C$30-1)/12))/(C$16*(1+Assumptions!$C$10+Assumptions!$C$34*(Assumptions!$C$30-1)/12)+Assumptions!$C$41*Assumptions!$C$34) -> 7944819.6 | D17: =(12*$B17*Assumptions!$C$5*(1-Assumptions!$C$41-Assumptions!$C$39)-Assumptions!$C$41*(Assumptions!$C$36+Assumptions!$C$37)*Assumptions!$C$5-D$16*(Assumptions!$C$19+(Assumptions!$C$28*Assumptions!$C$5)+(Assumptions!$C$29*$B17*Assumptions!$C$5*Assumptions!$C$25)+(Assumptions!$C$36+Assumptions!$C$37)*Assumptions!$C$5*(Assumptions!$C$30-1)/12))/(D$16*(1+Assumptions!$C$10+Assumptions!$C$34*(Assumptions!$C$30-1)/12)+Assumptions!$C$41*Assumptions!$C$34) -> 7541375.8 | E17: =(12*$B17*Assumptions!$C$5*(1-Assumptions!$C$41-Assumptions!$C$39)-Assumptions!$C$41*(Assumptions!$C$36+Assumptions!$C$37)*Assumptions!$C$5-E$16*(Assumptions!$C$19+(Assumptions!$C$28*Assumptions!$C$5)+(Assumptions!$C$29*$B17*Assumptions!$C$5*Assumptions!$C$25)+(Assumptions!$C$36+Assumptions!$C$37)*Assumptions!$C$5*(Assumptions!$C$30-1)/12))/(E$16*(1+Assumptions!$C$10+Assumptions!$C$34*(Assumptions!$C$30-1)/12)+Assumptions!$C$41*Assumptions!$C$34) -> 7168691 | F17: =(12*$B17*Assumptions!$C$5*(1-Assumptions!$C$41-Assumptions!$C$39)-Assumptions!$C$41*(Assumptions!$C$36+Assumptions!$C$37)*Assumptions!$C$5-F$16*(Assumptions!$C$19+(Assumptions!$C$28*Assumptions!$C$5)+(Assumptions!$C$29*$B17*Assumptions!$C$5*Assumptions!$C$25)+(Assumptions!$C$36+Assumptions!$C$37)*Assumptions!$C$5*(Assumptions!$C$30-1)/12))/(F$16*(1+Assumptions!$C$10+Assumptions!$C$34*(Assumptions!$C$30-1)/12)+Assumptions!$C$41*Assumptions!$C$34) -> 6823376.7 | G17: =(12*$B17*Assumptions!$C$5*(1-Assumptions!$C$41-Assumptions!$C$39)-Assumptions!$C$41*(Assumptions!$C$36+Assumptions!$C$37)*Assumptions!$C$5-G$16*(Assumptions!$C$19+(Assumptions!$C$28*Assumptions!$C$5)+(Assumptions!$C$29*$B17*Assumptions!$C$5*Assumptions!$C$25)+(Assumptions!$C$36+Assumptions!$C$37)*Assumptions!$C$5*(Assumptions!$C$30-1)/12))/(G$16*(1+Assumptions!$C$10+Assumptions!$C$34*(Assumptions!$C$30-1)/12)+Assumptions!$C$41*Assumptions!$C$34) -> 6502524.5
B18: 1.9 | C18: =(12*$B18*Assumptions!$C$5*(1-Assumptions!$C$41-Assumptions!$C$39)-Assumptions!$C$41*(Assumptions!$C$36+Assumptions!$C$37)*Assumptions!$C$5-C$16*(Assumptions!$C$19+(Assumptions!$C$28*Assumptions!$C$5)+(Assumptions!$C$29*$B18*Assumptions!$C$5*Assumptions!$C$25)+(Assumptions!$C$36+Assumptions!$C$37)*Assumptions!$C$5*(Assumptions!$C$30-1)/12))/(C$16*(1+Assumptions!$C$10+Assumptions!$C$34*(Assumptions!$C$30-1)/12)+Assumptions!$C$41*Assumptions!$C$34) -> 8502080.8 | D18: =(12*$B18*Assumptions!$C$5*(1-Assumptions!$C$41-Assumptions!$C$39)-Assumptions!$C$41*(Assumptions!$C$36+Assumptions!$C$37)*Assumptions!$C$5-D$16*(Assumptions!$C$19+(Assumptions!$C$28*Assumptions!$C$5)+(Assumptions!$C$29*$B18*Assumptions!$C$5*Assumptions!$C$25)+(Assumptions!$C$36+Assumptions!$C$37)*Assumptions!$C$5*(Assumptions!$C$30-1)/12))/(D$16*(1+Assumptions!$C$10+Assumptions!$C$34*(Assumptions!$C$30-1)/12)+Assumptions!$C$41*Assumptions!$C$34) -> 8076182.3 | E18: =(12*$B18*Assumptions!$C$5*(1-Assumptions!$C$41-Assumptions!$C$39)-Assumptions!$C$41*(Assumptions!$C$36+Assumptions!$C$37)*Assumptions!$C$5-E$16*(Assumptions!$C$19+(Assumptions!$C$28*Assumptions!$C$5)+(Assumptions!$C$29*$B18*Assumptions!$C$5*Assumptions!$C$25)+(Assumptions!$C$36+Assumptions!$C$37)*Assumptions!$C$5*(Assumptions!$C$30-1)/12))/(E$16*(1+Assumptions!$C$10+Assumptions!$C$34*(Assumptions!$C$30-1)/12)+Assumptions!$C$41*Assumptions!$C$34) -> 7682754.8 | F18: =(12*$B18*Assumptions!$C$5*(1-Assumptions!$C$41-Assumptions!$C$39)-Assumptions!$C$41*(Assumptions!$C$36+Assumptions!$C$37)*Assumptions!$C$5-F$16*(Assumptions!$C$19+(Assumptions!$C$28*Assumptions!$C$5)+(Assumptions!$C$29*$B18*Assumptions!$C$5*Assumptions!$C$25)+(Assumptions!$C$36+Assumptions!$C$37)*Assumptions!$C$5*(Assumptions!$C$30-1)/12))/(F$16*(1+Assumptions!$C$10+Assumptions!$C$34*(Assumptions!$C$30-1)/12)+Assumptions!$C$41*Assumptions!$C$34) -> 7318221.3 | G18: =(12*$B18*Assumptions!$C$5*(1-Assumptions!$C$41-Assumptions!$C$39)-Assumptions!$C$41*(Assumptions!$C$36+Assumptions!$C$37)*Assumptions!$C$5-G$16*(Assumptions!$C$19+(Assumptions!$C$28*Assumptions!$C$5)+(Assumptions!$C$29*$B18*Assumptions!$C$5*Assumptions!$C$25)+(Assumptions!$C$36+Assumptions!$C$37)*Assumptions!$C$5*(Assumptions!$C$30-1)/12))/(G$16*(1+Assumptions!$C$10+Assumptions!$C$34*(Assumptions!$C$30-1)/12)+Assumptions!$C$41*Assumptions!$C$34) -> 6979511.4
B19: 2 | C19: =(12*$B19*Assumptions!$C$5*(1-Assumptions!$C$41-Assumptions!$C$39)-Assumptions!$C$41*(Assumptions!$C$36+Assumptions!$C$37)*Assumptions!$C$5-C$16*(Assumptions!$C$19+(Assumptions!$C$28*Assumptions!$C$5)+(Assumptions!$C$29*$B19*Assumptions!$C$5*Assumptions!$C$25)+(Assumptions!$C$36+Assumptions!$C$37)*Assumptions!$C$5*(Assumptions!$C$30-1)/12))/(C$16*(1+Assumptions!$C$10+Assumptions!$C$34*(Assumptions!$C$30-1)/12)+Assumptions!$C$41*Assumptions!$C$34) -> 9059341.9 | D19: =(12*$B19*Assumptions!$C$5*(1-Assumptions!$C$41-Assumptions!$C$39)-Assumptions!$C$41*(Assumptions!$C$36+Assumptions!$C$37)*Assumptions!$C$5-D$16*(Assumptions!$C$19+(Assumptions!$C$28*Assumptions!$C$5)+(Assumptions!$C$29*$B19*Assumptions!$C$5*Assumptions!$C$25)+(Assumptions!$C$36+Assumptions!$C$37)*Assumptions!$C$5*(Assumptions!$C$30-1)/12))/(D$16*(1+Assumptions!$C$10+Assumptions!$C$34*(Assumptions!$C$30-1)/12)+Assumptions!$C$41*Assumptions!$C$34) -> 8610988.8 | E19: =(12*$B19*Assumptions!$C$5*(1-Assumptions!$C$41-Assumptions!$C$39)-Assumptions!$C$41*(Assumptions!$C$36+Assumptions!$C$37)*Assumptions!$C$5-E$16*(Assumptions!$C$19+(Assumptions!$C$28*Assumptions!$C$5)+(Assumptions!$C$29*$B19*Assumptions!$C$5*Assumptions!$C$25)+(Assumptions!$C$36+Assumptions!$C$37)*Assumptions!$C$5*(Assumptions!$C$30-1)/12))/(E$16*(1+Assumptions!$C$10+Assumptions!$C$34*(Assumptions!$C$30-1)/12)+Assumptions!$C$41*Assumptions!$C$34) -> 8196818.7 | F19: =(12*$B19*Assumptions!$C$5*(1-Assumptions!$C$41-Assumptions!$C$39)-Assumptions!$C$41*(Assumptions!$C$36+Assumptions!$C$37)*Assumptions!$C$5-F$16*(Assumptions!$C$19+(Assumptions!$C$28*Assumptions!$C$5)+(Assumptions!$C$29*$B19*Assumptions!$C$5*Assumptions!$C$25)+(Assumptions!$C$36+Assumptions!$C$37)*Assumptions!$C$5*(Assumptions!$C$30-1)/12))/(F$16*(1+Assumptions!$C$10+Assumptions!$C$34*(Assumptions!$C$30-1)/12)+Assumptions!$C$41*Assumptions!$C$34) -> 7813065.9 | G19: =(12*$B19*Assumptions!$C$5*(1-Assumptions!$C$41-Assumptions!$C$39)-Assumptions!$C$41*(Assumptions!$C$36+Assumptions!$C$37)*Assumptions!$C$5-G$16*(Assumptions!$C$19+(Assumptions!$C$28*Assumptions!$C$5)+(Assumptions!$C$29*$B19*Assumptions!$C$5*Assumptions!$C$25)+(Assumptions!$C$36+Assumptions!$C$37)*Assumptions!$C$5*(Assumptions!$C$30-1)/12))/(G$16*(1+Assumptions!$C$10+Assumptions!$C$34*(Assumptions!$C$30-1)/12)+Assumptions!$C$41*Assumptions!$C$34) -> 7456498.2
B20: 2.1 | C20: =(12*$B20*Assumptions!$C$5*(1-Assumptions!$C$41-Assumptions!$C$39)-Assumptions!$C$41*(Assumptions!$C$36+Assumptions!$C$37)*Assumptions!$C$5-C$16*(Assumptions!$C$19+(Assumptions!$C$28*Assumptions!$C$5)+(Assumptions!$C$29*$B20*Assumptions!$C$5*Assumptions!$C$25)+(Assumptions!$C$36+Assumptions!$C$37)*Assumptions!$C$5*(Assumptions!$C$30-1)/12))/(C$16*(1+Assumptions!$C$10+Assumptions!$C$34*(Assumptions!$C$30-1)/12)+Assumptions!$C$41*Assumptions!$C$34) -> 9616603 | D20: =(12*$B20*Assumptions!$C$5*(1-Assumptions!$C$41-Assumptions!$C$39)-Assumptions!$C$41*(Assumptions!$C$36+Assumptions!$C$37)*Assumptions!$C$5-D$16*(Assumptions!$C$19+(Assumptions!$C$28*Assumptions!$C$5)+(Assumptions!$C$29*$B20*Assumptions!$C$5*Assumptions!$C$25)+(Assumptions!$C$36+Assumptions!$C$37)*Assumptions!$C$5*(Assumptions!$C$30-1)/12))/(D$16*(1+Assumptions!$C$10+Assumptions!$C$34*(Assumptions!$C$30-1)/12)+Assumptions!$C$41*Assumptions!$C$34) -> 9145795.4 | E20: =(12*$B20*Assumptions!$C$5*(1-Assumptions!$C$41-Assumptions!$C$39)-Assumptions!$C$41*(Assumptions!$C$36+Assumptions!$C$37)*Assumptions!$C$5-E$16*(Assumptions!$C$19+(Assumptions!$C$28*Assumptions!$C$5)+(Assumptions!$C$29*$B20*Assumptions!$C$5*Assumptions!$C$25)+(Assumptions!$C$36+Assumptions!$C$37)*Assumptions!$C$5*(Assumptions!$C$30-1)/12))/(E$16*(1+Assumptions!$C$10+Assumptions!$C$34*(Assumptions!$C$30-1)/12)+Assumptions!$C$41*Assumptions!$C$34) -> 8710882.6 | F20: =(12*$B20*Assumptions!$C$5*(1-Assumptions!$C$41-Assumptions!$C$39)-Assumptions!$C$41*(Assumptions!$C$36+Assumptions!$C$37)*Assumptions!$C$5-F$16*(Assumptions!$C$19+(Assumptions!$C$28*Assumptions!$C$5)+(Assumptions!$C$29*$B20*Assumptions!$C$5*Assumptions!$C$25)+(Assumptions!$C$36+Assumptions!$C$37)*Assumptions!$C$5*(Assumptions!$C$30-1)/12))/(F$16*(1+Assumptions!$C$10+Assumptions!$C$34*(Assumptions!$C$30-1)/12)+Assumptions!$C$41*Assumptions!$C$34) -> 8307910.5 | G20: =(12*$B20*Assumptions!$C$5*(1-Assumptions!$C$41-Assumptions!$C$39)-Assumptions!$C$41*(Assumptions!$C$36+Assumptions!$C$37)*Assumptions!$C$5-G$16*(Assumptions!$C$19+(Assumptions!$C$28*Assumptions!$C$5)+(Assumptions!$C$29*$B20*Assumptions!$C$5*Assumptions!$C$25)+(Assumptions!$C$36+Assumptions!$C$37)*Assumptions!$C$5*(Assumptions!$C$30-1)/12))/(G$16*(1+Assumptions!$C$10+Assumptions!$C$34*(Assumptions!$C$30-1)/12)+Assumptions!$C$41*Assumptions!$C$34) -> 7933485.1
B21: 2.2 | C21: =(12*$B21*Assumptions!$C$5*(1-Assumptions!$C$41-Assumptions!$C$39)-Assumptions!$C$41*(Assumptions!$C$36+Assumptions!$C$37)*Assumptions!$C$5-C$16*(Assumptions!$C$19+(Assumptions!$C$28*Assumptions!$C$5)+(Assumptions!$C$29*$B21*Assumptions!$C$5*Assumptions!$C$25)+(Assumptions!$C$36+Assumptions!$C$37)*Assumptions!$C$5*(Assumptions!$C$30-1)/12))/(C$16*(1+Assumptions!$C$10+Assumptions!$C$34*(Assumptions!$C$30-1)/12)+Assumptions!$C$41*Assumptions!$C$34) -> 10173864 | D21: =(12*$B21*Assumptions!$C$5*(1-Assumptions!$C$41-Assumptions!$C$39)-Assumptions!$C$41*(Assumptions!$C$36+Assumptions!$C$37)*Assumptions!$C$5-D$16*(Assumptions!$C$19+(Assumptions!$C$28*Assumptions!$C$5)+(Assumptions!$C$29*$B21*Assumptions!$C$5*Assumptions!$C$25)+(Assumptions!$C$36+Assumptions!$C$37)*Assumptions!$C$5*(Assumptions!$C$30-1)/12))/(D$16*(1+Assumptions!$C$10+Assumptions!$C$34*(Assumptions!$C$30-1)/12)+Assumptions!$C$41*Assumptions!$C$34) -> 9680601.9 | E21: =(12*$B21*Assumptions!$C$5*(1-Assumptions!$C$41-Assumptions!$C$39)-Assumptions!$C$41*(Assumptions!$C$36+Assumptions!$C$37)*Assumptions!$C$5-E$16*(Assumptions!$C$19+(Assumptions!$C$28*Assumptions!$C$5)+(Assumptions!$C$29*$B21*Assumptions!$C$5*Assumptions!$C$25)+(Assumptions!$C$36+Assumptions!$C$37)*Assumptions!$C$5*(Assumptions!$C$30-1)/12))/(E$16*(1+Assumptions!$C$10+Assumptions!$C$34*(Assumptions!$C$30-1)/12)+Assumptions!$C$41*Assumptions!$C$34) -> 9224946.5 | F21: =(12*$B21*Assumptions!$C$5*(1-Assumptions!$C$41-Assumptions!$C$39)-Assumptions!$C$41*(Assumptions!$C$36+Assumptions!$C$37)*Assumptions!$C$5-F$16*(Assumptions!$C$19+(Assumptions!$C$28*Assumptions!$C$5)+(Assumptions!$C$29*$B21*Assumptions!$C$5*Assumptions!$C$25)+(Assumptions!$C$36+Assumptions!$C$37)*Assumptions!$C$5*(Assumptions!$C$30-1)/12))/(F$16*(1+Assumptions!$C$10+Assumptions!$C$34*(Assumptions!$C$30-1)/12)+Assumptions!$C$41*Assumptions!$C$34) -> 8802755.2 | G21: =(12*$B21*Assumptions!$C$5*(1-Assumptions!$C$41-Assumptions!$C$39)-Assumptions!$C$41*(Assumptions!$C$36+Assumptions!$C$37)*Assumptions!$C$5-G$16*(Assumptions!$C$19+(Assumptions!$C$28*Assumptions!$C$5)+(Assumptions!$C$29*$B21*Assumptions!$C$5*Assumptions!$C$25)+(Assumptions!$C$36+Assumptions!$C$37)*Assumptions!$C$5*(Assumptions!$C$30-1)/12))/(G$16*(1+Assumptions!$C$10+Assumptions!$C$34*(Assumptions!$C$30-1)/12)+Assumptions!$C$41*Assumptions!$C$34) -> 8410471.9
